PS C:\Products\projects\python> & c:/Products/projects/python/venv/Scripts/python.exe c:/Products/projects/python/database_operations/runner.py
test 0 Function                                                  Create Table
Table Name                                                    TEST0001
Column Name          ID: INT,\nNAME: VARCHAR,\nPHONE: VARCHAR,\nEMA...
Contraint                                                       ID: PK
Values                                                             NaN
Expected Checksum                                                  NaN
Checksum Type                                                      NaN
Name: 0, dtype: object
'Function' Traceback (most recent call last):
  File "C:\Products\projects\python\venv\Lib\site-packages\pandas\core\indexes\base.py", line 3805, in get_loc
    return self._engine.get_loc(casted_key)
           ~~~~~~~~~~~~~~~~~~~~^^^^^^^^^^^^
  File "index.pyx", line 167, in pandas._libs.index.IndexEngine.get_loc
  File "index.pyx", line 196, in pandas._libs.index.IndexEngine.get_loc
  File "pandas\\_libs\\hashtable_class_helper.pxi", line 7081, in pandas._libs.hashtable.PyObjectHashTable.get_item
  File "pandas\\_libs\\hashtable_class_helper.pxi", line 7089, in pandas._libs.hashtable.PyObjectHashTable.get_item
KeyError: 'Function'

The above exception was the direct cause of the following exception:

Traceback (most recent call last):
  File "c:\Products\projects\python\database_operations\runner.py", line 104, in <module>
    process_validation(host, user,password, validation_df)
    ~~~~~~~~~~~~~~~~~~^^^^^^^^^^^^^^^^^^^^^^^^^^^^^^^^^^^^
  File "c:\Products\projects\python\database_operations\runner.py", line 17, in process_validation
    function = row['Function']
               ~~~^^^^^^^^^^^^
  File "C:\Products\projects\python\venv\Lib\site-packages\pandas\core\series.py", line 1121, in __getitem__
    return self._get_value(key)
           ~~~~~~~~~~~~~~~^^^^^
  File "C:\Products\projects\python\venv\Lib\site-packages\pandas\core\series.py", line 1237, in _get_value
    loc = self.index.get_loc(label)
  File "C:\Products\projects\python\venv\Lib\site-packages\pandas\core\indexes\base.py", line 3812, in get_loc
    raise KeyError(key) from err
KeyError: 'Function'
